<?xml version="1.0" ?>
<!-- =================================================================================== -->
<!-- |    This document was autogenerated by xacro from /home/user/widowx_arm/src/widowx_arm_description/urdf/widowx.urdf.xacro | -->
<!-- |    EDITING THIS FILE BY HAND IS NOT RECOMMENDED                                 | -->
<!-- =================================================================================== -->
<robot xmlns:xacro="http://ros.org/wiki/xacro" name="widowx">
      <link name="arm_base_link">
         <visual>
            <origin xyz="0 0 0" rpy="0 0 0" />
            <geometry>
               <mesh filename="package://widowx_arm_description/meshes/base_link.stl"/>
            </geometry>
            <xacro:material_black />
	     </visual>
         <collision>
            <origin xyz="0 0 0" rpy="0 0 0" />
            <geometry>
               <mesh filename="package://widowx_arm_description/meshes/base_link.stl"/>
            </geometry>
         </collision>
         <inertial>
            <origin xyz="0 0 0" rpy="0 0 0" />
            <mass value="1" />
            <inertia ixx="1.0" ixy="0.0" ixz="0.0" iyy="1.0" iyz="0.0" izz="1.0" />
         </inertial>
      </link>
      <link name="shoulder_link">
         <visual>
            <origin xyz="0 0 0" rpy="0 0 0" />
            <geometry>
               <mesh filename="package://widowx_arm_description/meshes/shoulder_link.stl" />
            </geometry>
            <xacro:material_black />
         </visual>
         <collision>
            <origin xyz="0 0 0" rpy="0 0 0" />
            <geometry>
               <mesh filename="package://widowx_arm_description/meshes/shoulder_link.stl"/>
            </geometry>
         </collision>
         <inertial>
            <origin xyz="0 0 0" rpy="0 0 0" />
            <mass value="1" />
            <inertia ixx="1.0" ixy="0.0" ixz="0.0" iyy="1.0" iyz="0.0" izz="1.0" />
         </inertial>
      </link>
      <link name="biceps_link">
         <visual>
            <origin xyz="0 0 0" rpy="0 0 0" />
            <geometry>
               <mesh filename="package://widowx_arm_description/meshes/biceps_link.new.stl" />
            </geometry>
            <xacro:material_black />
         </visual>
         <collision>
            <origin xyz="0 0 0" rpy="0 0 0" />
            <geometry>
               <mesh filename="package://widowx_arm_description/meshes/biceps_link.new.stl" />
            </geometry>
         </collision>
         <inertial>
            <origin xyz="0 0 0" rpy="0 0 0" />
            <mass value="1" />
            <inertia ixx="1.0" ixy="0.0" ixz="0.0" iyy="1.0" iyz="0.0" izz="1.0" />
         </inertial>
      </link>
      <link name="forearm_link">
         <visual>
            <origin xyz="0 0 0" rpy="0 0 0" />
            <geometry>
               <mesh filename="package://widowx_arm_description/meshes/forearm_link.new.stl"/>
            </geometry>
           <xacro:material_black />
         </visual>
         <collision>
            <origin xyz="0 0 0" rpy="0 0 0" />
            <geometry>
               <mesh filename="package://widowx_arm_description/meshes/forearm_link.new.stl"/>
            </geometry>
         </collision>
         <inertial>
            <origin xyz="0 0 0" rpy="0 0 0" />
            <mass value="1" />
            <inertia ixx="1.0" ixy="0.0" ixz="0.0" iyy="1.0" iyz="0.0" izz="1.0"/>
         </inertial>
      </link>
      <link name="wrist_1_link">
         <visual>
            <origin xyz="0 0 0" rpy="0 0 0" />
            <geometry>
               <mesh filename="package://widowx_arm_description/meshes/wrist_1_link.stl"/>
            </geometry>
            <xacro:material_black />
         </visual>
         <collision>
            <origin xyz="0 0 0" rpy="0 0 0" />
            <geometry>
               <mesh filename="package://widowx_arm_description/meshes/wrist_1_link.stl"/>
            </geometry>
         </collision>
         <inertial>
            <origin xyz="0 0 0" rpy="0 0 0" />
            <mass value="1" />
            <inertia ixx="1.0" ixy="0.0" ixz="0.0" iyy="1.0" iyz="0.0" izz="1.0" />
         </inertial>
      </link>
      <link name="wrist_2_link">
         <visual>
            <origin xyz="0 0 0" rpy="0 0 0" />
            <geometry>
               <mesh filename="package://widowx_arm_description/meshes/wrist_2_link.new.stl"/>
            </geometry>
            <xacro:material_black />
         </visual>
         <collision>
            <origin xyz="0 0 0" rpy="0 0 0" />
            <geometry>
               <mesh filename="package://widowx_arm_description/meshes/wrist_2_link.new.stl"/>
            </geometry>
         </collision>
         <inertial>
            <origin xyz="0 0 0" rpy="0 0 0" />
            <mass value="1" />
            <inertia ixx="1.0" ixy="0.0" ixz="0.0" iyy="1.0" iyz="0.0" izz="1.0" />
         </inertial>
      </link>
      <link name="wrist_3_dummy_link">
         <visual>
            <origin xyz="0 0 0" rpy="0 0 0" />
            <geometry>
		<sphere radius="0.001"/>
            </geometry>
            <xacro:material_black />
         </visual>
         <collision>
            <origin xyz="0 0 0" rpy="0 0 0" />
            <geometry>
		<sphere radius="0.001"/>
            </geometry>
         </collision>
         <inertial>
            <origin xyz="0 0 0" rpy="0 0 0" />
            <mass value="1" />
            <inertia ixx="1.0" ixy="0.0" ixz="0.0" iyy="1.0" iyz="0.0" izz="1.0" />
         </inertial>
      </link>


      <joint name="joint_1" type="revolute">
         <origin xyz="0 0 0.125" rpy="0 0 0" />
         <parent link="arm_base_link" />
         <child link="shoulder_link" />
         <axis xyz="0 0 1" />
         <limit lower="-2.617" upper="2.617" effort="6" velocity="0.785" />
      </joint>
      <joint name="joint_2" type="revolute">
         <!--origin xyz="0.04825 0 0.14203" rpy="0 0 0" /-->
         <origin xyz="0 0 0" rpy="0 0 0" />
         <parent link="shoulder_link" />
         <child link="biceps_link" />
         <axis xyz="0 1 0" />
         <limit lower="-1.571" upper="1.571" effort="6" velocity="1.571" />
      </joint>
      <joint name="joint_3" type="revolute">
         <origin xyz="0.04825 0 0.14203" rpy="0 1.570795 0" />
         <parent link="biceps_link" />
         <child link="forearm_link" />
         <axis xyz="0 1 0" />
         <limit lower="-1.571" upper="1.571" effort="6" velocity="1.571" />
      </joint>
      <joint name="joint_4" type="revolute">
         <origin xyz="0 0 0.14203" rpy="0 0 0" />
         <parent link="forearm_link" />
         <child link="wrist_1_link" />
         <axis xyz="0 1 0" />
         <limit lower="-1.745" upper="1.745" effort="6" velocity="1.571" />
      </joint>
      <joint name="joint_5" type="revolute">
         <origin xyz="0 0 0.0715" rpy="0 0 0" />
         <parent link="wrist_1_link" />
         <child link="wrist_2_link" />
         <axis xyz="0 0 1" />
         <limit lower="-2.617" upper="2.617" effort="6" velocity="1.571" />
      </joint>
      <joint name="joint_6_dummy" type="fixed">
         <origin xyz="0.01 0 0.03" rpy="0 0 0" />
         <parent link="wrist_2_link" />
         <child link="wrist_3_dummy_link" />
      </joint>

  <transmission name="tran1">
    <type>transmission_interface/SimpleTransmission</type>
    <joint name="joint_1">
      <hardwareInterface>EffortJointInterface</hardwareInterface>
    </joint>
    <actuator name="motor1">
      <mechanicalReduction>1</mechanicalReduction>
    </actuator>
  </transmission>
  <transmission name="tran2">
    <type>transmission_interface/SimpleTransmission</type>
    <joint name="joint_2">
      <hardwareInterface>EffortJointInterface</hardwareInterface>
    </joint>
    <actuator name="motor2">
      <mechanicalReduction>1</mechanicalReduction>
    </actuator>
  </transmission>
  <transmission name="tran3">
    <type>transmission_interface/SimpleTransmission</type>
    <joint name="joint_3">
      <hardwareInterface>EffortJointInterface</hardwareInterface>
    </joint>
    <actuator name="motor3">
      <mechanicalReduction>1</mechanicalReduction>
    </actuator>
  </transmission>
  <transmission name="tran4">
    <type>transmission_interface/SimpleTransmission</type>
    <joint name="joint_4">
      <hardwareInterface>EffortJointInterface</hardwareInterface>
    </joint>
    <actuator name="motor4">
      <mechanicalReduction>1</mechanicalReduction>
    </actuator>
  </transmission>
  <transmission name="tran5">
    <type>transmission_interface/SimpleTransmission</type>
    <joint name="joint_5">
      <hardwareInterface>EffortJointInterface</hardwareInterface>
    </joint>
    <actuator name="motor5">
      <mechanicalReduction>1</mechanicalReduction>
    </actuator>
  </transmission>
  <transmission name="tran6">
    <type>transmission_interface/SimpleTransmission</type>
    <joint name="gripper_prismatic_joint_1">
      <hardwareInterface>EffortJointInterface</hardwareInterface>
    </joint>
    <actuator name="motor6">
      <mechanicalReduction>1</mechanicalReduction>
    </actuator>
  </transmission>
</robot>

